Workbook

Sheet sickness data
A1: OWC | B1: REGION | C1: CULTURE | D1: N passages (750, 751, 752, 753) | E1: Reading1:Who? | F1: Reading2:Who? | G1: First coding | H1: Second coding | I1: Info: Original sickness dataset, this dataset was used in the initial machine learning training and includes all passages of 750-753 except for duplicates that share OCMS (and blanks) note that this is slightly different from the new dataset nonsickness which removes all deplicates even if they do not share OCMS
A2: mw11 | B2: Africa | C2: Shluh | D2: 1 | E2: NOTE:these may not have enough info for coding - will be examined later
A3: es10 | B3: Europe | C3: Highland Scots | D3: 7 | E3: NOTE:these may not have enough info for coding - will be examined later
A4: ma11 | B4: Middle-East | C4: Kurds | D4: 12 | E4: RA LG
A5: ax04 | B5: Asia | C5: Sinhalese | D5: 12
A6: ms14 | B6: Africa | C6: Kanuri | D6: 15
A7: fq05 | B7: Africa | C7: Bemba | D7: 17
A8: oj29 | B8: Oceania | C8: Kapauku | D8: 18
A9: ms30 | B9: Africa | C9: Wolof | D9: 23
A10: so11 | B10: South-America | C10: Bahia Brazilians | D10: 23
A11: ar07 | B11: Asia | C11: Khasi | D11: 25
A12: sm04 | B12: South-America | C12: Guaraní | D12: 27
A13: nr10 | B13: North-America | C13: Klamath | D13: 29
A14: ol06 | B14: Oceania | C14: Trobriands | D14: 29 | E14: RA HL
A15: rv02 | B15: Asia | C15: Yakut | D15: 30 | E15: RA HL
A16: nd08 | B16: North-America | C16: Copper Inuit | D16: 33 | E16: RA LG | F16: RA YM
A17: fo04 | B17: Africa | C17: Mbuti | D17: 34
A18: oq06 | B18: Oceania | C18: Lau Fijians | D18: 39 | E18: RA YM
A19: fq09 | B19: Africa | C19: Lozi | D19: 40 | E19: RA HL | F19: RA LG | H19: UNFINISHED - LG
A20: sr15 | B20: South-America | C20: Saramaka | D20: 44
A21: si07 | B21: South-America | C21: Mataco | D21: 45 | E21: RA AH | G21: UNFINISHED - AH
A22: nq18 | B22: North-America | C22: Pawnee | D22: 46 | E22: RA LG | F22: RA YM | H22: UNFINISHED -YM
A23: sp08 | B23: South-America | C23: Bororo | D23: 47 | E23: RA HL
A24: mt09 | B24: Africa | C24: Libyan Bedouin | D24: 49 | E24: RA YM | F24: RA LG | H24: Not Started - LG
A25: sc07 | B25: South-America | C25: Kogi | D25: 52 | E25: RA LG | F25: RA YM | H25: Not Started - YM
A26: sq18 | B26: South-America | C26: Yanoama | D26: 55 | E26: RA LG
A27: oi08 | B27: Oceania | C27: Aranda | D27: 63 | E27: RA KK
A28: fl12 | B28: Africa | C28: Maasai | D28: 66 | E28: RA KY
A29: ep04 | B29: Europe | C29: Saami | D29: 66 | E29: RA AH
A30: mo04 | B30: Africa | C30: Somali | D30: 69 | E30: RA HL
A31: sh04 | B31: South-America | C31: Ona | D31: 69 | E31: RA YM
A32: sq19 | B32: South-America | C32: Tukano | D32: 73 | E32: RA LG
A33: ot11 | B33: Oceania | C33: Tikopia | D33: 74 | E33: RA YM
A34: ms12 | B34: Africa | C34: Hausa | D34: 77 | E34: RA KY
A35: nf06 | B35: North-America | C35: Blackfoot | D35: 83 | E35: RA AH
A36: nv09 | B36: Middle-America-and-the-Caribbean | C36: Tzeltal | D36: 83 | E36: RA KK
A37: fk07 | B37: Africa | C37: Ganda | D37: 84 | E37: RA KY
... A40: sf05 | B40: South-America | C40: Aymara | D40: 97 | E40: RA HL
A41: oc06 | B41: Asia | C41: Iban | D41: 104 | E41: RA KY | G41: UNFINISHED - KY
A42: aa01 | B42: Asia | C42: Korea | D42: 107
...

Sheet sickness and nonsickness data
A1: OWC | B1: Region | C1: Culture | D1: Partition | E1: Total Cultural Passage Count | F1: Partition Passage Count | G1: Reading1:Who? | H1: Reading2:Who? | I1: First coding | J1: Second coding | K1: info: This dataset is mant to be the continuation of the originally scraped dataset 750-753 which was found to potentially not have enough false instances of misfortune. We then scraped a new set of OCMs ["780", "781", "784", "785", '586' , '684' , '688' , '731' , '732' , '756' , '767' , '777' , '791' , '792' , '793' , '431' , '572' , '594' , '613' , '624' , '675' , '853'] which composed of misfortune and non-misfortune OCMS. Our new coding attempts to use many of the old misfortune dataset passages but including a balanced non-sickness dataset of OCMS ['784' , '731' , '732' , '777' , '791', '793']. Note that unlike the other dataset previously coded (the sinkess 750-753) this new altogether dataset (composed of the sickness and nonsickness datasets) removes all duplicated even if they share OCMS and is a bit more critical of odd in passage notes like if they contain "[ a ]" or "[unavailable]" | L1: Lookup sickness dataset RAs
A2: mw11 | B2: Africa | C2: Shluh | D2: 1 | E2: 2 | F2: 2 | L2: =VLOOKUP($C2,'sickness data'!$C$2:$E$61,3,FALSE) -> NOTE:these may not have enough info for coding - will be examined later | M2: may not keep
A3: es10 | B3: Europe | C3: Highland Scots | D3: 1 | E3: 14 | F3: 14 | L3: =VLOOKUP(C3,'sickness data'!C$2:E$61,3,FALSE) -> NOTE:these may not have enough info for coding - will be examined later | M3: may not keep
A4: ma11 | B4: Middle-East | C4: Kurds | D4: 1 | E4: 19 | F4: 19 | G4: RA KW | L4: =VLOOKUP(C4,'sickness data'!C$2:E$61,3,FALSE) -> RA LG
A5: ax04 | B5: Asia | C5: Sinhalese | D5: 1 | E5: 20 | F5: 20 | G5: RA KB | I5: DONE | L5: =VLOOKUP(C5,'sickness data'!C$2:E$61,3,FALSE) -> 0 | N5: =IF(L5=0,IF(I5="",1,""),"")
A6: ms14 | B6: Africa | C6: Kanuri | D6: 1 | E6: 28 | F6: 28 | G6: RA LR | I6: DONE | L6: =VLOOKUP(C6,'sickness data'!C$2:E$61,3,FALSE) -> 0 | N6: =IF(L6=0,IF(I6="",1,""),"")
A7: oj29 | B7: Oceania | C7: Kapauku | D7: 1 | E7: 34 | F7: 34 | G7: RA BK | L7: =VLOOKUP(C7,'sickness data'!C$2:E$61,3,FALSE) -> 0 | N7: =IF(L7=0,IF(I7="",1,""),"") -> 1
A8: fq05 | B8: Africa | C8: Bemba | D8: 1 | E8: 34 | F8: 34 | G8: RA SJ | I8: DONE | L8: =VLOOKUP(C8,'sickness data'!C$2:E$61,3,FALSE) -> 0 | N8: =IF(L8=0,IF(I8="",1,""),"")
A9: so11 | B9: South-America | C9: Bahia Brazilians | D9: 1 | E9: 41 | F9: 41 | G9: RA KW | I9: DONE | L9: =VLOOKUP(C9,'sickness data'!C$2:E$61,3,FALSE) -> 0 | N9: =IF(L9=0,IF(I9="",1,""),"")
A10: sm04 | B10: South-America | C10: Guaraní | D10: 1 | E10: 45 | F10: 45 | G10: RA BK | I10: DONE | L10: =VLOOKUP(C10,'sickness data'!C$2:E$61,3,FALSE) -> 0 | N10: =IF(L10=0,IF(I10="",1,""),"")
A11: ms30 | B11: Africa | C11: Wolof | D11: 1 | E11: 46 | F11: 46 | G11: RA BK | I11: DONE | L11: =VLOOKUP(C11,'sickness data'!C$2:E$61,3,FALSE) -> 0 | N11: =IF(L11=0,IF(I11="",1,""),"")
A12: ar07 | B12: Asia | C12: Khasi | D12: 1 | E12: 48 | F12: 48 | G12: RA JH | I12: DONE | L12: =VLOOKUP(C12,'sickness data'!C$2:E$61,3,FALSE) -> 0 | N12: =IF(L12=0,IF(I12="",1,""),"")
A13: rv02 | B13: Asia | C13: Yakut | D13: 1 | E13: 52 | F13: 52 | G13: RA KW | L13: =VLOOKUP(C13,'sickness data'!C$2:E$61,3,FALSE) -> RA HL | N13: =IF(L13=0,IF(I13="",1,""),"")
A14: nr10 | B14: North-America | C14: Klamath | D14: 1 | E14: 55 | F14: 55 | G14: RA SJ | L14: =VLOOKUP(C14,'sickness data'!C$2:E$61,3,FALSE) -> 0 | N14: =IF(OR(L14=0,M14="Unfinished"),IF(I14="",1,""),"") -> 1
A15: ol06 | B15: Oceania | C15: Trobriands | D15: 1 | E15: 56 | F15: 56 | G15: RA BK | L15: =VLOOKUP(C15,'sickness data'!C$2:E$61,3,FALSE) -> RA HL | N15: =IF(OR(L15=0,M15="Unfinished"),IF(I15="",1,""),"")
A16: nd08 | B16: North-America | C16: Copper Inuit | D16: 1 | E16: 62 | F16: 62 | G16: RA BK | L16: =VLOOKUP(C16,'sickness data'!C$2:E$61,3,FALSE) -> RA LG | N16: =IF(OR(L16=0,M16="Unfinished"),IF(I16="",1,""),"")
A17: si07 | B17: South-America | C17: Mataco | D17: 1 | E17: 65 | F17: 65 | G17: RA LR | L17: =VLOOKUP(C17,'sickness data'!C$2:E$61,3,FALSE) -> RA AH | M17: UNFINISHED | N17: =IF(OR(L17=0,M17="Unfinished"),IF(I17="",1,""),"") -> 1
A18: fo04 | B18: Africa | C18: Mbuti | D18: 1 | E18: 65 | F18: 65 | G18: RA SJ | I18: DONE | L18: =VLOOKUP(C18,'sickness data'!C$2:E$61,3,FALSE) -> 0 | N18: =IF(OR(L18=0,M18="Unfinished"),IF(I18="",1,""),"")
A19: sc07 | B19: South-America | C19: Kogi | D19: 1 | E19: 73 | F19: 73 | G19: RA KB | L19: =VLOOKUP(C19,'sickness data'!C$2:E$61,3,FALSE) -> RA LG | N19: =IF(OR(L19=0,M19="Unfinished"),IF(I19="",1,""),"")
A20: fq09 | B20: Africa | C20: Lozi | D20: 1 | E20: 74 | F20: 74 | L20: =VLOOKUP(C20,'sickness data'!C$2:E$61,3,FALSE) -> RA HL | N20: =IF(OR(L20=0,M20="Unfinished"),IF(I20="",1,""),"")
A21: oq06 | B21: Oceania | C21: Lau Fijians | D21: 1 | E21: 77 | F21: 77 | L21: =VLOOKUP(C21,'sickness data'!C$2:E$61,3,FALSE) -> RA YM | N21: =IF(OR(L21=0,M21="Unfinished"),IF(I21="",1,""),"")
A22: sr15 | B22: South-America | C22: Saramaka | D22: 1 | E22: 79 | F22: 79 | G22: RA KW | I22: DONE | L22: =VLOOKUP(C22,'sickness data'!C$2:E$61,3,FALSE) -> 0 | N22: =IF(OR(L22=0,M22="Unfinished"),IF(I22="",1,""),"")
A23: nq18 | B23: North-America | C23: Pawnee | D23: 1 | E23: 84 | F23: 84 | L23: =VLOOKUP(C23,'sickness data'!C$2:E$61,3,FALSE) -> RA LG | N23: =IF(OR(L23=0,M23="Unfinished"),IF(I23="",1,""),"")
A24: sp08 | B24: South-America | C24: Bororo | D24: 1 | E24: 89 | F24: 89 | L24: =VLOOKUP(C24,'sickness data'!C$2:E$61,3,FALSE) -> RA HL | N24: =IF(OR(L24=0,M24="Unfinished"),IF(I24="",1,""),"")
A25: mt09 | B25: Africa | C25: Libyan Bedouin | D25: 1 | E25: 98 | F25: 98 | L25: =VLOOKUP(C25,'sickness data'!C$2:E$61,3,FALSE) -> RA YM | N25: =IF(OR(L25=0,M25="Unfinished"),IF(I25="",1,""),"")
A26: ep04 | B26: Europe | C26: Saami | D26: 1 | E26: 101 | F26: 101 | L26: =VLOOKUP(C26,'sickness data'!C$2:E$61,3,FALSE) -> RA AH | N26: =IF(OR(L26=0,M26="Unfinished"),IF(I26="",1,""),"")
A27: sq18 | B27: South-America | C27: Yanoama | D27: 1 | E27: 102 | F27: 102 | G27: RA BK | I27: DONE | L27: =VLOOKUP(C27,'sickness data'!C$2:E$61,3,FALSE) -> RA LG | N27: =IF(OR(L27=0,M27="Unfinished"),IF(I27="",1,""),"")
A28: fl12 | B28: Africa | C28: Maasai | D28: 1 | E28: 107 | F28: 107 | L28: =VLOOKUP(C28,'sickness data'!C$2:E$61,3,FALSE) -> RA KY | N28: =IF(OR(L28=0,M28="Unfinished"),IF(I28="",1,""),"")
A29: ot11 | B29: Oceania | C29: Tikopia | D29: 1 | E29: 117 | F29: 117 | L29: =VLOOKUP(C29,'sickness data'!C$2:E$61,3,FALSE) -> RA YM | N29: =IF(OR(L29=0,M29="Unfinished"),IF(I29="",1,""),"")
A30: oi08 | B30: Oceania | C30: Aranda | D30: 1 | E30: 122 | F30: 122 | L30: =VLOOKUP(C30,'sickness data'!C$2:E$61,3,FALSE) -> RA KK | N30: =IF(OR(L30=0,M30="Unfinished"),IF(I30="",1,""),"")
A31: mo04 | B31: Africa | C31: Somali | D31: 1 | E31: 123 | F31: 123 | L31: =VLOOKUP(C31,'sickness data'!C$2:E$61,3,FALSE) -> RA HL | N31: =IF(OR(L31=0,M31="Unfinished"),IF(I31="",1,""),"")
A32: sh04 | B32: South-America | C32: Ona | D32: 1 | E32: 136 | F32: 136 | L32: =VLOOKUP(C32,'sickness data'!C$2:E$61,3,FALSE) -> RA YM | N32: =IF(OR(L32=0,M32="Unfinished"),IF(I32="",1,""),"")
A33: sq19 | B33: South-America | C33: Tukano | D33: 1 | E33: 138 | F33: 138 | L33: =VLOOKUP(C33,'sickness data'!C$2:E$61,3,FALSE) -> RA LG | N33: =IF(OR(L33=0,M33="Unfinished"),IF(I33="",1,""),"")
A34: fk07 | B34: Africa | C34: Ganda | D34: 1 | E34: 143 | F34: 143 | L34: =VLOOKUP(C34,'sickness data'!C$2:E$61,3,FALSE) -> RA KY | N34: =IF(OR(L34=0,M34="Unfinished"),IF(I34="",1,""),"")
A35: nf06 | B35: North-America | C35: Blackfoot | D35: 1 | E35: 148 | F35: 148 | L35: =VLOOKUP(C35,'sickness data'!C$2:E$61,3,FALSE) -> RA AH | N35: =IF(OR(L35=0,M35="Unfinished"),IF(I35="",1,""),"")
A36: ms12 | B36: Africa | C36: Hausa | D36: 1 | E36: 149 | F36: 149 | G36: RA SJ | L36: =VLOOKUP(C36,'sickness data'!C$2:E$61,3,FALSE) -> RA KY | N36: =IF(OR(L36=0,M36="Unfinished"),IF(I36="",1,""),"")
A37: nv09 | B37: Middle-America-and-the-Caribbean | C37: Tzeltal | D37: 1 | E37: 151 | F37: 151 | L37: =VLOOKUP(C37,'sickness data'!C$2:E$61,3,FALSE) -> RA KK | N37: =IF(OR(L37=0,M37="Unfinished"),IF(I37="",1,""),"")
A38: aw42 | B38: Asia | C38: Santal | D38: 1 | E38: 167 | F38: 167 | G38: RA SJ | L38: =VLOOKUP(C38,'sickness data'!C$2:E$61,3,FALSE) -> RA LG | N38: =IF(OR(L38=0,M38="Unfinished"),IF(I38="",1,""),"")
A39: nu33 | B39: Middle-America-and-the-Caribbean | C39: Tarahumara | D39: 1 | E39: 171 | F39: 171 | G39: RA MJ | I39: DONE | L39: =VLOOKUP(C39,'sickness data'!C$2:E$61,3,FALSE) -> 0 | N39: =IF(OR(L39=0,M39="Unfinished"),IF(I39="",1,""),"")
A40: az02 | B40: Asia | C40: Andamans | D40: 1 | E40: 176 | F40: 176 | L40: =VLOOKUP(C40,'sickness data'!C$2:E$61,3,FALSE) -> RA YM | N40: =IF(OR(L40=0,M40="Unfinished"),IF(I40="",1,""),"")
...

Sheet OCM 750 and 780 comparison
B1: 750-753 | C1: ["780", "781", "784", "785"] | G1: ["780", "781", "784", "785", "788"]
A2: Culture | B2: 750 | C2: 780 | D2: percentage | E2: log abs ratio | F2: Adequate | G2: 780 | H2: percentage | I2: log abs ratio | J2: Adequate
A3: Shluh | B3: 1 | C3: 20 | D3: 0.05 | E3: 3 | F3: =IF(OR(D3<0.4, D3>0.6),IF(OR(D3<0.3, D3>0.7),0,0.5),1) -> 0 | G3: 26 | H3: 0.04 | I3: 3.26 | J3: =IF(OR(H3<0.4, H3>0.6),IF(OR(H3<0.3, H3>0.7),0,0.5),1) -> 0 | K3: NOTE:these may not have enough info for coding - will be examined later
A4: Highland Scots | B4: 7 | C4: 50 | D4: 0.12 | E4: 1.97 | F4: =IF(OR(D4<0.4, D4>0.6),IF(OR(D4<0.3, D4>0.7),0,0.5),1) -> 0 | G4: 86 | H4: 0.08 | I4: 2.51 | J4: =IF(OR(H4<0.4, H4>0.6),IF(OR(H4<0.3, H4>0.7),0,0.5),1) -> 0 | K4: NOTE:these may not have enough info for coding - will be examined later
A5: Sinhalese | B5: 10 | C5: 18 | D5: 0.36 | E5: 0.59 | F5: =IF(OR(D5<0.4, D5>0.6),IF(OR(D5<0.3, D5>0.7),0,0.5),1) -> 0.5 | G5: 53 | H5: 0.16 | I5: 1.67 | J5: =IF(OR(H5<0.4, H5>0.6),IF(OR(H5<0.3, H5>0.7),0,0.5),1) -> 0 | K5: RA LG
A6: Kurds | B6: 10 | C6: 17 | D6: 0.37 | E6: 0.53 | F6: =IF(OR(D6<0.4, D6>0.6),IF(OR(D6<0.3, D6>0.7),0,0.5),1) -> 0.5 | G6: 62 | H6: 0.14 | I6: 1.82 | J6: =IF(OR(H6<0.4, H6>0.6),IF(OR(H6<0.3, H6>0.7),0,0.5),1) -> 0
A7: Kanuri | B7: 14 | C7: 17 | D7: 0.45 | E7: 0.19 | F7: =IF(OR(D7<0.4, D7>0.6),IF(OR(D7<0.3, D7>0.7),0,0.5),1) -> 1 | G7: 29 | H7: 0.33 | I7: 0.73 | J7: =IF(OR(H7<0.4, H7>0.6),IF(OR(H7<0.3, H7>0.7),0,0.5),1) -> 0.5
A8: Kapauku | B8: 17 | C8: 90 | D8: 0.16 | E8: 1.67 | F8: =IF(OR(D8<0.4, D8>0.6),IF(OR(D8<0.3, D8>0.7),0,0.5),1) -> 0 | G8: 92 | H8: 0.16 | I8: 1.69 | J8: =IF(OR(H8<0.4, H8>0.6),IF(OR(H8<0.3, H8>0.7),0,0.5),1) -> 0
A9: Bemba | B9: 17 | C9: 45 | D9: 0.27 | E9: 0.97 | F9: =IF(OR(D9<0.4, D9>0.6),IF(OR(D9<0.3, D9>0.7),0,0.5),1) -> 0 | G9: 80 | H9: 0.18 | I9: 1.55 | J9: =IF(OR(H9<0.4, H9>0.6),IF(OR(H9<0.3, H9>0.7),0,0.5),1) -> 0
A10: Bahia Brazilians | B10: 21 | C10: 9 | D10: 0.7 | E10: 0.85 | F10: =IF(OR(D10<0.4, D10>0.6),IF(OR(D10<0.3, D10>0.7),0,0.5),1) -> 0.5 | G10: 22 | H10: 0.49 | I10: 0.05 | J10: =IF(OR(H10<0.4, H10>0.6),IF(OR(H10<0.3, H10>0.7),0,0.5),1) -> 1
A11: Guaraní | B11: 23 | C11: 30 | D11: 0.43 | E11: 0.27 | F11: =IF(OR(D11<0.4, D11>0.6),IF(OR(D11<0.3, D11>0.7),0,0.5),1) -> 1 | G11: 33 | H11: 0.41 | I11: 0.36 | J11: =IF(OR(H11<0.4, H11>0.6),IF(OR(H11<0.3, H11>0.7),0,0.5),1) -> 1
A12: Wolof | B12: 23 | C12: 11 | D12: 0.68 | E12: 0.74 | F12: =IF(OR(D12<0.4, D12>0.6),IF(OR(D12<0.3, D12>0.7),0,0.5),1) -> 0.5 | G12: 25 | H12: 0.48 | I12: 0.08 | J12: =IF(OR(H12<0.4, H12>0.6),IF(OR(H12<0.3, H12>0.7),0,0.5),1) -> 1
A13: Khasi | B13: 24 | C13: 30 | D13: 0.44 | E13: 0.22 | F13: =IF(OR(D13<0.4, D13>0.6),IF(OR(D13<0.3, D13>0.7),0,0.5),1) -> 1 | G13: 30 | H13: 0.44 | I13: 0.22 | J13: =IF(OR(H13<0.4, H13>0.6),IF(OR(H13<0.3, H13>0.7),0,0.5),1) -> 1
A14: Yakut | B14: 26 | C14: 9 | D14: 0.74 | E14: 1.06 | F14: =IF(OR(D14<0.4, D14>0.6),IF(OR(D14<0.3, D14>0.7),0,0.5),1) -> 0 | G14: 9 | H14: 0.74 | I14: 1.06 | J14: =IF(OR(H14<0.4, H14>0.6),IF(OR(H14<0.3, H14>0.7),0,0.5),1) -> 0
A15: Trobriands | B15: 28 | C15: 129 | D15: 0.18 | E15: 1.53 | F15: =IF(OR(D15<0.4, D15>0.6),IF(OR(D15<0.3, D15>0.7),0,0.5),1) -> 0 | G15: 141 | H15: 0.17 | I15: 1.62 | J15: =IF(OR(H15<0.4, H15>0.6),IF(OR(H15<0.3, H15>0.7),0,0.5),1) -> 0 | K15: RA HL
A16: Klamath | B16: 29 | C16: 15 | D16: 0.66 | E16: 0.66 | F16: =IF(OR(D16<0.4, D16>0.6),IF(OR(D16<0.3, D16>0.7),0,0.5),1) -> 0.5 | G16: 16 | H16: 0.64 | I16: 0.59 | J16: =IF(OR(H16<0.4, H16>0.6),IF(OR(H16<0.3, H16>0.7),0,0.5),1) -> 0.5 | K16: RA HL
A17: Copper Inuit | B17: 31 | C17: 96 | D17: 0.24 | E17: 1.13 | F17: =IF(OR(D17<0.4, D17>0.6),IF(OR(D17<0.3, D17>0.7),0,0.5),1) -> 0 | G17: 97 | H17: 0.24 | I17: 1.14 | J17: =IF(OR(H17<0.4, H17>0.6),IF(OR(H17<0.3, H17>0.7),0,0.5),1) -> 0 | K17: RA LG
A18: Mbuti | B18: 33 | C18: 31 | D18: 0.52 | E18: 0.06 | F18: =IF(OR(D18<0.4, D18>0.6),IF(OR(D18<0.3, D18>0.7),0,0.5),1) -> 1 | G18: 39 | H18: 0.46 | I18: 0.17 | J18: =IF(OR(H18<0.4, H18>0.6),IF(OR(H18<0.3, H18>0.7),0,0.5),1) -> 1
A19: Lozi | B19: 37 | C19: 10 | D19: 0.79 | E19: 1.31 | F19: =IF(OR(D19<0.4, D19>0.6),IF(OR(D19<0.3, D19>0.7),0,0.5),1) -> 0 | G19: 14 | H19: 0.73 | I19: 0.97 | J19: =IF(OR(H19<0.4, H19>0.6),IF(OR(H19<0.3, H19>0.7),0,0.5),1) -> 0 | K19: RA YM
A20: Kogi | B20: 37 | C20: 61 | D20: 0.38 | E20: 0.5 | F20: =IF(OR(D20<0.4, D20>0.6),IF(OR(D20<0.3, D20>0.7),0,0.5),1) -> 0.5 | G20: 81 | H20: 0.31 | I20: 0.78 | J20: =IF(OR(H20<0.4, H20>0.6),IF(OR(H20<0.3, H20>0.7),0,0.5),1) -> 0.5 | K20: RA HL
A21: Lau Fijians | B21: 39 | C21: 15 | D21: 0.72 | E21: 0.96 | F21: =IF(OR(D21<0.4, D21>0.6),IF(OR(D21<0.3, D21>0.7),0,0.5),1) -> 0 | G21: 16 | H21: 0.71 | I21: 0.89 | J21: =IF(OR(H21<0.4, H21>0.6),IF(OR(H21<0.3, H21>0.7),0,0.5),1) -> 0
A22: Saramaka | B22: 40 | C22: 32 | D22: 0.56 | E22: 0.22 | F22: =IF(OR(D22<0.4, D22>0.6),IF(OR(D22<0.3, D22>0.7),0,0.5),1) -> 1 | G22: 33 | H22: 0.55 | I22: 0.19 | J22: =IF(OR(H22<0.4, H22>0.6),IF(OR(H22<0.3, H22>0.7),0,0.5),1) -> 1 | K22: RA AH
A23: Pawnee | B23: 42 | C23: 26 | D23: 0.62 | E23: 0.48 | F23: =IF(OR(D23<0.4, D23>0.6),IF(OR(D23<0.3, D23>0.7),0,0.5),1) -> 0.5 | G23: 53 | H23: 0.44 | I23: 0.23 | J23: =IF(OR(H23<0.4, H23>0.6),IF(OR(H23<0.3, H23>0.7),0,0.5),1) -> 1 | K23: RA LG | N23: {=N23:O45} -> 0
A24: Mataco | B24: 45 | C24: 6 | D24: 0.88 | E24: 2.01 | F24: =IF(OR(D24<0.4, D24>0.6),IF(OR(D24<0.3, D24>0.7),0,0.5),1) -> 0 | G24: 6 | H24: 0.88 | I24: 2.01 | J24: =IF(OR(H24<0.4, H24>0.6),IF(OR(H24<0.3, H24>0.7),0,0.5),1) -> 0 | K24: RA HL
A25: Bororo | B25: 46 | C25: 48 | D25: 0.49 | E25: 0.04 | F25: =IF(OR(D25<0.4, D25>0.6),IF(OR(D25<0.3, D25>0.7),0,0.5),1) -> 1 | G25: 53 | H25: 0.46 | I25: 0.14 | J25: =IF(OR(H25<0.4, H25>0.6),IF(OR(H25<0.3, H25>0.7),0,0.5),1) -> 1 | K25: RA YM
A26: Libyan Bedouin | B26: 49 | C26: 27 | D26: 0.64 | E26: 0.6 | F26: =IF(OR(D26<0.4, D26>0.6),IF(OR(D26<0.3, D26>0.7),0,0.5),1) -> 0.5 | G26: 30 | H26: 0.62 | I26: 0.49 | J26: =IF(OR(H26<0.4, H26>0.6),IF(OR(H26<0.3, H26>0.7),0,0.5),1) -> 0.5 | K26: RA LG
A27: Saami | B27: 51 | C27: 54 | D27: 0.49 | E27: 0.06 | F27: =IF(OR(D27<0.4, D27>0.6),IF(OR(D27<0.3, D27>0.7),0,0.5),1) -> 1 | G27: 73 | H27: 0.41 | I27: 0.36 | J27: =IF(OR(H27<0.4, H27>0.6),IF(OR(H27<0.3, H27>0.7),0,0.5),1) -> 1 | K27: RA LG
A28: Yanoama | B28: 54 | C28: 17 | D28: 0.76 | E28: 1.16 | F28: =IF(OR(D28<0.4, D28>0.6),IF(OR(D28<0.3, D28>0.7),0,0.5),1) -> 0 | G28: 19 | H28: 0.74 | I28: 1.04 | J28: =IF(OR(H28<0.4, H28>0.6),IF(OR(H28<0.3, H28>0.7),0,0.5),1) -> 0 | K28: RA KK
A29: Maasai | B29: 54 | C29: 28 | D29: 0.66 | E29: 0.66 | F29: =IF(OR(D29<0.4, D29>0.6),IF(OR(D29<0.3, D29>0.7),0,0.5),1) -> 0.5 | G29: 40 | H29: 0.57 | I29: 0.3 | J29: =IF(OR(H29<0.4, H29>0.6),IF(OR(H29<0.3, H29>0.7),0,0.5),1) -> 1 | K29: RA KY
A30: Tikopia | B30: 60 | C30: 184 | D30: 0.25 | E30: 1.12 | F30: =IF(OR(D30<0.4, D30>0.6),IF(OR(D30<0.3, D30>0.7),0,0.5),1) -> 0 | G30: 409 | H30: 0.13 | I30: 1.92 | J30: =IF(OR(H30<0.4, H30>0.6),IF(OR(H30<0.3, H30>0.7),0,0.5),1) -> 0 | K30: RA AH
A31: Aranda | B31: 62 | C31: 129 | D31: 0.32 | E31: 0.73 | F31: =IF(OR(D31<0.4, D31>0.6),IF(OR(D31<0.3, D31>0.7),0,0.5),1) -> 0.5 | G31: 195 | H31: 0.24 | I31: 1.15 | J31: =IF(OR(H31<0.4, H31>0.6),IF(OR(H31<0.3, H31>0.7),0,0.5),1) -> 0 | K31: RA HL
A32: Somali | B32: 62 | C32: 23 | D32: 0.73 | E32: 0.99 | F32: =IF(OR(D32<0.4, D32>0.6),IF(OR(D32<0.3, D32>0.7),0,0.5),1) -> 0 | G32: 48 | H32: 0.56 | I32: 0.26 | J32: =IF(OR(H32<0.4, H32>0.6),IF(OR(H32<0.3, H32>0.7),0,0.5),1) -> 1 | K32: RA YM
A33: Ona | B33: 68 | C33: 57 | D33: 0.54 | E33: 0.18 | F33: =IF(OR(D33<0.4, D33>0.6),IF(OR(D33<0.3, D33>0.7),0,0.5),1) -> 1 | G33: 59 | H33: 0.54 | I33: 0.14 | J33: =IF(OR(H33<0.4, H33>0.6),IF(OR(H33<0.3, H33>0.7),0,0.5),1) -> 1 | K33: RA LG
A34: Tukano | B34: 69 | C34: 72 | D34: 0.49 | E34: 0.04 | F34: =IF(OR(D34<0.4, D34>0.6),IF(OR(D34<0.3, D34>0.7),0,0.5),1) -> 1 | G34: 76 | H34: 0.48 | I34: 0.1 | J34: =IF(OR(H34<0.4, H34>0.6),IF(OR(H34<0.3, H34>0.7),0,0.5),1) -> 1 | K34: RA YM
A35: Ganda | B35: 73 | C35: 16 | D35: 0.82 | E35: 1.52 | F35: =IF(OR(D35<0.4, D35>0.6),IF(OR(D35<0.3, D35>0.7),0,0.5),1) -> 0 | G35: 53 | H35: 0.58 | I35: 0.32 | J35: =IF(OR(H35<0.4, H35>0.6),IF(OR(H35<0.3, H35>0.7),0,0.5),1) -> 1 | K35: RA KY
... A42: Iban | B42: 95 | C42: 134 | D42: 0.41 | E42: 0.34 | F42: =IF(OR(D42<0.4, D42>0.6),IF(OR(D42<0.3, D42>0.7),0,0.5),1) -> 1 | G42: 219 | H42: 0.3 | I42: 0.84 | J42: =IF(OR(H42<0.4, H42>0.6),IF(OR(H42<0.3, H42>0.7),0,0.5),1) -> 0.5 | K42: RA KY
A43: Korea | B43: 103 | C43: 82 | D43: 0.56 | E43: 0.23 | F43: =IF(OR(D43<0.4, D43>0.6),IF(OR(D43<0.3, D43>0.7),0,0.5),1) -> 1 | G43: 198 | H43: 0.34 | I43: 0.65 | J43: =IF(OR(H43<0.4, H43>0.6),IF(OR(H43<0.3, H43>0.7),0,0.5),1) -> 0.5
A44: Tlingit | B44: 111 | C44: 203 | D44: 0.35 | E44: 0.6 | F44: =IF(OR(D44<0.4, D44>0.6),IF(OR(D44<0.3, D44>0.7),0,0.5),1) -> 0.5 | G44: 259 | H44: 0.3 | I44: 0.85 | J44: =IF(OR(H44<0.4, H44>0.6),IF(OR(H44<0.3, H44>0.7),0,0.5),1) -> 0.5
A45: Azande | B45: 114 | C45: 47 | D45: 0.71 | E45: 0.89 | F45: =IF(OR(D45<0.4, D45>0.6),IF(OR(D45<0.3, D45>0.7),0,0.5),1) -> 0 | G45: 47 | H45: 0.71 | I45: 0.89 | J45: =IF(OR(H45<0.4, H45>0.6),IF(OR(H45<0.3, H45>0.7),0,0.5),1) -> 0
A46: Dogon | B46: 120 | C46: 376 | D46: 0.24 | E46: 1.14 | F46: =IF(OR(D46<0.4, D46>0.6),IF(OR(D46<0.3, D46>0.7),0,0.5),1) -> 0 | G46: 451 | H46: 0.21 | I46: 1.32 | J46: =IF(OR(H46<0.4, H46>0.6),IF(OR(H46<0.3, H46>0.7),0,0.5),1) -> 0
...

Sheet PB-NewList
A1: OWC | B1: REGION | C1: CULTURE | D1: N passages (750, 751, 752, 753) | E1: Reading1 by | F1: Status | G1: Reading2 by: | H1: Status
A2: si07 | B2: South-America | C2: Mataco | D2: 45 | E2: RA AH | F2: UNFINISHED - AH
A3: ep04 | B3: Europe | C3: Saami | D3: 66 | E3: RA AH | F3: Done
A4: nf06 | B4: North-America | C4: Blackfoot | D4: 83 | E4: RA AH | F4: Done
A5: ad05 | B5: Asia | C5: Taiwan Hokkien | D5: 326 | E5: RA AH | F5: UNFINISHED - AH
A6: fq09 | B6: Africa | C6: Lozi | D6: 40 | E6: RA HL | F6: Done | G6: RA LG | H6: UNFINISHED - LG
A7: ol06 | B7: Oceania | C7: Trobriands | D7: 29 | E7: RA HL | F7: Done
A8: rv02 | B8: Asia | C8: Yakut | D8: 30 | E8: RA HL | F8: Done
A9: sp08 | B9: South-America | C9: Bororo | D9: 47 | E9: RA HL | F9: Done
A10: mo04 | B10: Africa | C10: Somali | D10: 69 | E10: RA HL | F10: Done
A11: sf05 | B11: South-America | C11: Aymara | D11: 97 | E11: RA HL | F11: Done
A12: oi08 | B12: Oceania | C12: Aranda | D12: 63 | E12: RA KK | F12: Done
A13: nv09 | B13: Middle-America-and-the-Caribbean | C13: Tzeltal | D13: 83 | E13: RA KK | F13: Done
A14: fl12 | B14: Africa | C14: Maasai | D14: 66 | E14: RA KY | F14: Done
A15: ms12 | B15: Africa | C15: Hausa | D15: 77 | E15: RA KY | F15: Done
A16: fk07 | B16: Africa | C16: Ganda | D16: 84 | E16: RA KY | F16: Done
A17: oc06 | B17: Asia | C17: Iban | D17: 104 | E17: RA KY | F17: UNFINISHED - KY
A18: nd08 | B18: North-America | C18: Copper Inuit | D18: 33 | E18: RA LG | F18: Done | G18: RA YM | H18: Done
A19: nq18 | B19: North-America | C19: Pawnee | D19: 46 | E19: RA LG | F19: Done | G19: RA YM | H19: UNFINISHED -YM
A20: sc07 | B20: South-America | C20: Kogi | D20: 52 | E20: RA LG | F20: Done | G20: RA YM | H20: Not Started - YM
A21: ma11 | B21: Middle-East | C21: Kurds | D21: 12 | E21: RA LG | F21: Done
A22: sq18 | B22: South-America | C22: Yanoama | D22: 55 | E22: RA LG | F22: Done
A23: sq19 | B23: South-America | C23: Tukano | D23: 73 | E23: RA LG | F23: Done
A24: aw42 | B24: Asia | C24: Santal | D24: 92 | E24: RA LG | F24: Done
A25: mt09 | B25: Africa | C25: Libyan Bedouin | D25: 49 | E25: RA YM | F25: Done | G25: RA LG | H25: Not Started - LG
A26: oq06 | B26: Oceania | C26: Lau Fijians | D26: 39 | E26: RA YM | F26: Done
A27: sh04 | B27: South-America | C27: Ona | D27: 69 | E27: RA YM | F27: Done
A28: ot11 | B28: Oceania | C28: Tikopia | D28: 74 | E28: RA YM | F28: Done
A29: az02 | B29: Asia | C29: Andamans | D29: 90 | E29: RA YM | F29: Done
A30: ry02 | B30: Asia | C30: Chukchee | D30: 180 | E30: RA YM | F30: Done
A31: ax04 | B31: Asia | C31: Sinhalese | D31: 12
A32: fq05 | B32: Africa | C32: Bemba | D32: 17
A33: oj29 | B33: Oceania | C33: Kapauku | D33: 18
A34: ms30 | B34: Africa | C34: Wolof | D34: 23
A35: so11 | B35: South-America | C35: Bahia Brazilians | D35: 23
A36: ar07 | B36: Asia | C36: Khasi | D36: 25
A37: sm04 | B37: South-America | C37: Guaraní | D37: 27
A38: nr10 | B38: North-America | C38: Klamath | D38: 29
A39: fo04 | B39: Africa | C39: Mbuti | D39: 34
A40: sr15 | B40: South-America | C40: Saramaka | D40: 44
...
